---
layout:  post
title:   Java编程思想笔记——通过异常处理错误1
date:   2018-04-16 22:30:47
author:  'zhangtao'
header-img: 'img/post-bg-2015.jpg'
catalog:   false
tags:
-Java编程思想

---



Java的基础理念是“结构不佳的代码不能运行”。错误恢复在我们所编写的程序中都是基本的要素，但在Java中它显得格外重要，因为Java的主要目标之一就是创建供他人使用的程序构件。  异常处理是Java唯一正式的错误报告机制。

## 概念

用强制规定地形式来消除错误处理过程中随心所欲的因素，这种做法由来已久，对异常处理地实现可以追溯到20世纪60年代的操作系统，甚至于BASIC语言种地on error goto语句。而C++的异常处理机制基于Ada，Java的异常处理则建立在C++的基础之上。  使用异常：能够降低错误处理代码的复杂度。

## 基本异常

异常情形(exceptional condition)是指阻止当前方法或作用域继续执行的问题。

#### 异常参数

异常对象也伴随着存储空间的分配和构造器的调用。所有标准异常类都有两个构造器：一个是默认构造器；另一个是接受字符串做为参数：  throw new NullPointerException(“t = null”);

关键字throw，在使用new创建了异常对象之后，此对象的引用将传给throw。尽管返回的异常对象其类型通常与方法设计的返回类型不同，但从效果上看，他就像从方法返回的。返回一个异常对象，然后退出方法或作用域。

## 捕获异常

监控区域(guarded region)，一段可能产生异常的代码

#### try块

如果方法抛出异常，这个方法将在抛出异常的过程中结束。要是不希望方法就此结束，可以在方法内设置特殊的块来捕获异常，try块。

#### 异常处理程序

异常处理程序紧跟try块，以关键字catch表示。

#### 终止与恢复

异常处理理论有两种基本模型，Java支持终止模型（它是Java和C++所支持的模型）。一旦异常被抛出，就表明错误已无法挽回，也不能回来继续执行。  另一种成为恢复模型。异常处理程序的工作是修正错误，然后重新尝试调用出问题的方法，并认为第二次成功。

## 创建自定义异常

要自定义异常，必须从已有的异常类继承，最好是选择意思相近的异常类继承。建立新的异常类型最简单的方法就是让编译器为你产生默认构造器：

```java
public class SimpleException extends Exception {
}
public class InheritingExceptions {
    public void f() throws SimpleException{
        System.out.println("Throw SimpleException from f()");
        throw new SimpleException();
    }

    public static void main(String[] args) {
        InheritingExceptions sed = new InheritingExceptions();
        try {
            sed.f();
        } catch (SimpleException e) {
            System.out.println("Caught it!");
        }
    }
}/*
Throw SimpleException from f()
Caught it!
*/
```

编译器创建了默认构造器，它将自动调用基类的默认构造器。对异常来说，最重要的部分就是类名。本例的结果被打印到了控制台上，输出显示系统正是在控制台上自动地捕获和测试这些结果的。但是，也许想通过写入System.err而将错误发送给标准错误流。通常这比把错误信息输出到System.out要好，因为System.out也许会被重定向。如果把结果送到System.err，它就不会随System.out一起被重定向，这样更容易被用户注意。

为异常类定义一个接受字符串参数的构造器：

```java
public class MyException extends Exception {
    public MyException() {}
    public MyException(String msg) {
        super(msg);
    }
}

public class FullConstructors {
    public static void f() throws MyException{
        System.out.println("Throwing MyException from f()");
        throw new MyException();
    }
    public static void g() throws MyException{
        System.out.println("Throwing MyException from g()");
        throw new MyException("Originated in g()");
    }

    public static void main(String[] args) {
        try {
            f();
        } catch (MyException e) {
            e.printStackTrace(System.out);
        }
        try {
            g();
        } catch (MyException e) {
            e.printStackTrace(System.out);
        }
    }
}/*
Throwing MyException from f()
thinking1.MyException
    at thinking1.FullConstructors.f(FullConstructors.java:6)
    at thinking1.FullConstructors.main(FullConstructors.java:15)
Throwing MyException from g()
thinking1.MyException: Originated in g()
    at thinking1.FullConstructors.g(FullConstructors.java:10)
    at thinking1.FullConstructors.main(FullConstructors.java:20)
*/
```

在异常处理程序中，调用了在Throwable类声明（Exception即从此类继承）的printStackTrace()方法。就像从输出中看到的，他将打印“从方法调用处直到异常抛出处”的方法调用序列。这里，信息被发送到了System.out，并自动被捕获和显示在输出中。但是，如果调用默认版本：  e.printStackTrace();  则信息将被输出到标准错误流。

#### 异常与记录日志

基本的日志记录功能：

```java
public class LoggingException extends Exception {
    private static Logger logger = Logger.getLogger("LoggingException");
    public LoggingException() {
        StringWriter trace = new StringWriter();
        printStackTrace(new PrintWriter(trace));
        logger.severe(trace.toString());
    }
}
public class LoggingExceptions {
    public static void main(String[] args) {
        try{
            throw new LoggingException();
        } catch (LoggingException e) {
            System.out.println("Caught " + e);
        }
        try {
            throw new LoggingException();
        } catch (LoggingException e) {
            System.out.println("Caught " + e);
        }
    }
}/*
Caught thinking1.LoggingException
四月 16, 2018 9:57:59 下午 thinking1.LoggingException <init>
严重: thinking1.LoggingException
    at thinking1.LoggingExceptions.main(LoggingExceptions.java:6)
Caught thinking1.LoggingException

四月 16, 2018 9:57:59 下午 thinking1.LoggingException <init>
严重: thinking1.LoggingException
    at thinking1.LoggingExceptions.main(LoggingExceptions.java:11)
*/
```

静态的Logger.getLogger()方法创建了一个String参数相关联的Logger对象（通常与错误相关的包名和类名），这个Logger对象会将其输出发送到System.err。向Logger写入的最简单方式就是直接调用与日志记录消息的级别相关联的方法，这里使用的是severe()。为了产生日志记录消息，我们欲获取异常抛出处的栈轨迹，但是printStackTrace()不会默认地产生字符串。为了获取字符串，我们需要使用重载的printStackTrace()方法，他接受一个java.io.PrintWriter对象作为参数。如果我们将一个java.io.StringWriter对象传递给这个PrintWriter的构造器，那么通过调用toString()方法，就可以将输出抽取为一个String。

更常见的情形是需要捕获和记录其他人编写的异常，在异常处理程序中生成日志消息：

```java
public class LoggingException2 {
    private static Logger logger = Logger.getLogger("LoggingException2");
    static void logException(Exception e) {
        StringWriter trace = new StringWriter();
        e.printStackTrace(new PrintWriter(trace));
        logger.severe(trace.toString());
    }

    public static void main(String[] args) {
        try{
            throw new NullPointerException();
        } catch (NullPointerException e) {
            logException(e);
        }
    }
}/*
四月 16, 2018 10:16:11 下午 thinking1.LoggingException2 logException
严重: java.lang.NullPointerException
    at thinking1.LoggingException2.main(LoggingException2.java:17)
*/
```

还可以进一步自定义异常，比如加入额外的构造器和成员：

```java
public class MyException2 extends Exception {
    private int x;
    public MyException2(){}
    public MyException2(String msg){
        super(msg);
    }
    public MyException2(String msg, int x){
        super(msg);
        this.x = x;
    }
    public int val(){
        return x;
    }
    @Override
    public String getMessage(){
        return "Detail Message: " + x + " " + super.getMessage();
    }
}

public class ExtraFeatures {
    public static void f() throws MyException2{
        System.out.println("Throwing MyException2 from f()");
        throw new MyException2();
    }
    public static void g() throws MyException2{
        System.out.println("Throwing MyException2 from g()");
        throw new MyException2("Originated in g()");
    }
    public static void h() throws MyException2{
        System.out.println("Throwing MyException2 from h()");
        throw new MyException2("Originated in h()", 47);
    }

    public static void main(String[] args) {
        try{
            f();
        } catch (MyException2 e) {
            e.printStackTrace(System.out);
        }
        try{
            g();
        } catch (MyException2 e) {
            e.printStackTrace(System.out);
        }
        try{
            h();
        } catch (MyException2 e) {
            e.printStackTrace(System.out);
            System.out.println("e.val() = " + e.val());
        }
    }
}/*
Throwing MyException2 from f()
thinking1.MyException2: Detail Message: 0 null
    at thinking1.ExtraFeatures.f(ExtraFeatures.java:6)
    at thinking1.ExtraFeatures.main(ExtraFeatures.java:19)
Throwing MyException2 from g()
thinking1.MyException2: Detail Message: 0 Originated in g()
    at thinking1.ExtraFeatures.g(ExtraFeatures.java:10)
    at thinking1.ExtraFeatures.main(ExtraFeatures.java:24)
Throwing MyException2 from h()
thinking1.MyException2: Detail Message: 47 Originated in h()
    at thinking1.ExtraFeatures.h(ExtraFeatures.java:14)
    at thinking1.ExtraFeatures.main(ExtraFeatures.java:29)
e.val() = 47
*/
```

新的异常添加了字段x以及设定x值的构造器和读取数据的方法。此外，还覆盖了Throwable.getMessage()方法，以产生更详细的信息。对于异常类来说，getMessage()方法有点类似于toString()方法。  既然异常也是对象的一种，所以可以继续修改这个异常类，已得到更强的功能。但要记住，使用程序包的客户端程序员可能仅仅只是查看一下抛出的异常类型，其他的就不管了，所以对异常所添加的其他功能也许根本用不上。

## 异常说明

把方法可能会抛出的异常告知使用此方法的客户端程序员。Java提供了相应的语法，使你能以礼貌的方式告知客户端程序员某个方法可能会抛出的异常类型，然后客户端程序员就可以进行相应的处理，这就是异常说明。  void f() throws TooBig, TooSmall, DivZero { //…

## 捕获所有异常

catch(Exception e) {  System.out.println(“Caught an exception”);  }  这将捕获所有异常，所以最好把他放在处理程序的末尾，以防它抢在其他处理程序之前先把异常捕获。  Exception可以调用其基类Throwable继承的方法：  String getMessage()  String getLocalizedMessage()  用来获取详细信息，或用本地语言表示的详细信息。

String toString()  返回对Throwable的简单描述，要是有详细信息的话，也会包含在内。

void printStackTrace()  void printStackTrace(PrintStream)  void printStackTrace(java.io.PrintWriter)  打印Throwable和Throwable的调用栈轨迹。调用栈显示了“把你带到异常抛出地点”的方法调用序列。其中第一个版本输出到标准错误，后两个版本允许选择要输出的流。

Throwable fillInStackTrace()  用于在Throwable对象的内部记录栈帧的当前状态。这在程序重新抛出错误或异常时很有用。

此外Throwable从基类Object继承的方法。对于异常来说，getClass()是个很好用的方法，他返回一个表示此对象类型的对象，然后可以使用getName()方法查询这个Class对象包含包信息的名称，或者使用只产生类名称的getSimpleName()方法。

```java
public class ExceptionMethods {
    public static void main(String[] args) {
        try{
            throw new Exception("My Exception");
        } catch (Exception e) {
            System.out.println("Caught Exception");
            System.out.println("getMessage(): " + e.getMessage());
            System.out.println("getLocalizedMessage(): " + e.getLocalizedMessage());
            System.out.println("toString(): " + e);
            System.out.println("printStackTrace(): ");
            e.printStackTrace(System.out);
        }
    }
}/*
Caught Exception
getMessage(): My Exception
getLocalizedMessage(): My Exception
toString(): java.lang.Exception: My Exception
printStackTrace(): 
java.lang.Exception: My Exception
    at thinking1.ExceptionMethods.main(ExceptionMethods.java:6)
*/
```

#### 栈轨迹

printStackTrace()方法所提供的信息可以通过getStackTrace()方法来访问，这个方法将返回一个由栈轨迹中的元素所构成的数组，其中每一个元素都表示栈中的一帧。元素0是栈顶元素，并且是调用序列中的最后一个方法调用。数组中的最后一个元素和栈底是调用序列中的第一个方法调用：

```java
public class WhoCalled {
    static void f() {
        try {
            throw new Exception();
        } catch (Exception e) {
            for(StackTraceElement ste : e.getStackTrace()){
                System.out.println(ste.getMethodName());
            }
        }
    }
    static void g(){f();}
    static void h(){g();}

    public static void main(String[] args) {
        f();
        System.out.println("--------------------------------");
        g();
        System.out.println("--------------------------------");
        h();
    }
}/*
f
main
--------------------------------
f
g
main
--------------------------------
f
g
h
main
*/
```

#### 重新抛出异常

有时希望把刚捕获的异常重新抛出，尤其是在使用Exception捕获所有异常的时候。既然已经得到了对当前异常对象的引用，可以直接把它重新抛出：  catch(Exception e){  System.out.println(“An exception was thrown”);  }  重新抛出异常会把异常抛给上一级环境中的异常处理程序，同一个try块的后续catch子句将被忽略。如果只是把当前异常对象重新抛出，那么printStackTrace()方法显示的将是原来异常抛出点的调用栈信息，而并非重新抛出点信息，要想更新这个信息，可以调用fillInStackTrace()方法，这将返回一个Throwable对象，它通过把当前调用栈信息填入原来那个异常对象而建立的：

```java
public class Rethrowing {
    public static void f() throws Exception{
        System.out.println("originating the exception in f()");
        throw new Exception("throw from f()");
    }
    public static void g() throws Exception{
        try {
            f();
        } catch (Exception e) {
            System.out.println("Inside g(),e.printStackTrace()");
            e.printStackTrace(System.out);
            throw e;
        }
    }
    public static void h() throws Exception{
        try {
            f();
        } catch (Exception e) {
            System.out.println("Inside h(),e.printStackTrace()");
            e.printStackTrace(System.out);
            throw (Exception) e.fillInStackTrace();
        }
    }

    public static void main(String[] args) {
        try {
            g();
        } catch (Exception e){
            System.out.println("main: printStackTrace()");
            e.printStackTrace(System.out);
        }
        try {
            h();
        } catch (Exception e){
            System.out.println("main: printStackTrace()");
            e.printStackTrace(System.out);
        }
    }
}/*
originating the exception in f()
Inside g(),e.printStackTrace()
java.lang.Exception: throw from f()
    at thinking1.Rethrowing.f(Rethrowing.java:6)
    at thinking1.Rethrowing.g(Rethrowing.java:10)
    at thinking1.Rethrowing.main(Rethrowing.java:29)
main: printStackTrace()
java.lang.Exception: throw from f()
    at thinking1.Rethrowing.f(Rethrowing.java:6)
    at thinking1.Rethrowing.g(Rethrowing.java:10)
    at thinking1.Rethrowing.main(Rethrowing.java:29)
originating the exception in f()
Inside h(),e.printStackTrace()
java.lang.Exception: throw from f()
    at thinking1.Rethrowing.f(Rethrowing.java:6)
    at thinking1.Rethrowing.h(Rethrowing.java:19)
    at thinking1.Rethrowing.main(Rethrowing.java:35)
main: printStackTrace()
java.lang.Exception: throw from f()
    at thinking1.Rethrowing.h(Rethrowing.java:23)
    at thinking1.Rethrowing.main(Rethrowing.java:35)
*/
```

调用fillInStackTrace()的那一行就成了异常的新发生地了。  有可能在捕获异常之后抛出另一种异常。效果类似与fillInStackTrace()，有关原来异常发生点的信息会丢失，剩下的是与新的抛出点有关的信息：

```java
public class OneException extends Exception {
    public OneException(String s){
        super(s);
    }
}
public class TwoException extends Exception{
    public TwoException(String s){
        super(s);
    }
}
public class RethrowNew {
    public static void f() throws OneException{
        System.out.println("originating the exception in f()");
        throw new OneException("thrown from f()");
    }

    public static void main(String[] args) {
        try {
            try {
                f();
            } catch (OneException e) {
                System.out.println("Caught in inner try, e.printStackTrace()");
                e.printStackTrace(System.out);
                throw new TwoException("from inner try");

            }
        } catch (TwoException e) {
            System.out.println("Caught in outer try, e.printStackTrace()");
            e.printStackTrace(System.out);
        }
    }
}/*
originating the exception in f()
Caught in inner try, e.printStackTrace()
thinking1.OneException: thrown from f()
    at thinking1.RethrowNew.f(RethrowNew.java:6)
    at thinking1.RethrowNew.main(RethrowNew.java:12)
Caught in outer try, e.printStackTrace()
thinking1.TwoException: from inner try
    at thinking1.RethrowNew.main(RethrowNew.java:16)
*/
```

最后那个异常仅知道自己来自main，而对f一无所知。  永远不要为清理一个异常对象而担心，或者说为异常对象的清理而担心。它们都是用new在堆上创建的对象，所以垃圾回收器会自动把他们清理掉。

#### 异常链

在捕获一个异常后抛出另一个异常，并希望把原始的异常信息保存下来，这被称为异常链。所有Throwable的子类在构造器中都可以接受一个cause对象最为参数，这个cause就用来表示原始异常。Throwable的子类中只有三种基本的异常类提供了带cause参数的构造器Error(Java虚拟机报告系统错误)、Exception以及RuntimeException。如果要把其他类型的异常链接起来，应该用initCause()方法而不是构造器。  下面的例子能让你在运动时动态地向DynamicFields对象添加字段：

```java
public class DynamicFieldsException extends Exception {
}
public class DynamicFields {
    private Object[][] fields;
    public DynamicFields(int initialSize){
        fields = new Object[initialSize][2];
        for(int i = 0 ; i < initialSize; i++){
            fields[i] = new Object[]{null, null};
        }
    }
    @Override
    public String toString(){
        StringBuffer result = new StringBuffer();
        for (Object[] obj : fields){
            result.append(obj[0]);
            result.append(": ");
            result.append(obj[1]);
            result.append("\n");
        }
        return result.toString();
    }
    private int hasField(String id){
        for(int i = 0; i < fields.length; i++){
            if(id.equals(fields[i][0])){
                return i;
            }
        }
        return -1;
    }
    private int getFiledNumber(String id) throws NoSuchFieldException{
        int fieldNum = hasField(id);
        if(fieldNum == -1){
            throw new NoSuchFieldException();
        }
        return fieldNum;
    }
    private int makeField(String id){
        for(int i = 0; i < fields.length; i++){
            if (fields[i][0] == null){
                fields[i][0] = id;
                return i;
            }
        }
        Object[][] tmp = new Object[fields.length + 1][2];
        for(int i = 0; i < fields.length; i++){
            tmp[i] = fields[i];
        }
        for(int i = fields.length; i < tmp.length; i++){
            tmp[i] = new Object[]{null, null};
        }
        fields = tmp;
        return makeField(id);
    }
    public Object getField(String id) throws NoSuchFieldException{
        return fields[getFiledNumber(id)][1];
    }
    public Object setField(String id, Object value) throws DynamicFieldsException {
        if(value == null){
            DynamicFieldsException dfe = new DynamicFieldsException();
            dfe.initCause(new NullPointerException());
            throw dfe;
        }
        int fieldNumber = hasField(id);
        if(fieldNumber == -1){
            fieldNumber = makeField(id);
        }
        Object result = null;
        try{
            result = getField(id);
        }catch (NoSuchFieldException e){
            throw new RuntimeException(e);
        }
        fields[fieldNumber][1] = value;
        return result;
    }

    public static void main(String[] args) {
        DynamicFields df = new DynamicFields(3);
        System.out.println(df);
        try{
            df.setField("d","A value for d");
            df.setField("number",47);
            df.setField("number2",48);
            System.out.println(df);
            df.setField("d","A new value for d");
            df.setField("number3",11);
            System.out.println("df: " + df);
            System.out.println("df.getField(\"d\"): " + df.getField("d"));
            Object field = df.setField("d",null);
        } catch (NoSuchFieldException e){
            e.printStackTrace(System.out);
        } catch (DynamicFieldsException e) {
            e.printStackTrace(System.out);
        }
    }
}/*
null: null
null: null
null: null

d: A value for d
number: 47
number2: 48

df: d: A new value for d
number: 47
number2: 48
number3: 11

df.getField("d"): A new value for d
thinking1.DynamicFieldsException
    at thinking1.DynamicFields.setField(DynamicFields.java:59)
    at thinking1.DynamicFields.main(DynamicFields.java:89)
Caused by: java.lang.NullPointerException
    at thinking1.DynamicFields.setField(DynamicFields.java:60)
    ... 1 more
*/
```

每个DynamicFields对象都含有一个数组，其元素是成对的对象。第一个表示字段标识符，第二个表示字段值，值的类型是除基本类型外的任意类型。当调用setField()方法时候，它将试图通过标识符修改已有的字段值，否则就建一个新的字段，并把值放入。如果空间不够了，将建立一个更长的数组，并把原来的数组元素复制进去。如果你试图为字段设置一个空值，将抛出一个DynamicFieldsException异常，它是通过使用initCause()方法把NullPointerException对象插入而建立的。  至于返回值，setField()将用getField()方法把此位置的旧值取出，这个操作可能会抛出NoSuchFieldException异常。如果客户端程序员调用了这个getField()方法，那么就有责任处理这个可能抛出的NoSuchFieldException异常，但如果是从setField()方法里抛出的，这种情况将被视为编程错误，所以就使用接受cause参数的构造器把NoSuchFieldException异常转换为RuntimeException异常。

